Workbook
Name ________cps2: '[1]Working Sheet'!$CQ$7:$CQ$9
Name ________cps3: '[1]Working Sheet'!$CQ$7:$CQ$9
Name _______cps2: '[1]Working Sheet'!$CQ$7:$CQ$9
Name _______cps3: '[1]Working Sheet'!$CQ$7:$CQ$9
Name ______cps2: '[1]Working Sheet'!$CQ$7:$CQ$9
Name ______cps3: '[1]Working Sheet'!$CQ$7:$CQ$9
Name _____cps2: '[1]Working Sheet'!$CQ$7:$CQ$9
Name _____cps3: '[1]Working Sheet'!$CQ$7:$CQ$9
Name ____cps2: '[1]Working Sheet'!$CQ$7:$CQ$9
Name ____cps3: '[1]Working Sheet'!$CQ$7:$CQ$9
Name ___cps2: '[1]Working Sheet'!$CQ$7:$CQ$9
Name ___cps3: '[1]Working Sheet'!$CQ$7:$CQ$9
Name __cps2: '[1]Working Sheet'!$CQ$7:$CQ$9
Name __cps3: '[1]Working Sheet'!$CQ$7:$CQ$9
Name _cps1: '[2]Working Sheet'!$CQ$7:$CQ$9
Name _cps2: '[1]Working Sheet'!$CQ$7:$CQ$9
Name _cps3: '[1]Working Sheet'!$CQ$7:$CQ$9
Name abc: #REF!
Name abc: #REF!
Name abc: #REF!
Name abc: #REF!
Name CleintSide: JavaReference!$A$5:$E$7
Name csharp: '[3]Learning Assets'!$B$4:$B$48
Name CSharp1: '[4]Learning Assets'!$B$4:$B$48
Name dffdafda: '[5]Learning Assets'!$B$4:$B$48
Name grtyrt: '[6]Learning Assets'!$B$4:$B$48
Name ImpFactor: '[7]Dotnet&CC Skills'!$E$121:$E$123
Name ModuleName: '[8]Learning Assets'!$B$4:$B$48
Name PL: #REF!
Name PL: #REF!
Name PL: #REF!
Name PL: #REF!
Name ProfLevel: '[7]Proficiency Level Desc'!$A$2:$A$6
Name ServerSide: JavaReference!$A$9:$E$11
Name Skill: [9]Skill!$N$7:$N$9
Name SkillCategory: '[10]Read Me'!$N$1:$N$4
Name tttt: '[11]Learning Assets'!$B$4:$B$48

Sheet About the Curriculum
A1: FSE - SET Role | Java Curriculum
A2: 1. Name of the track | B2: FSE Java
A4: 2. Category (Technical/Domain/Behavioral): | B4: Technical and Behavioral
A6: 3. Outcome Expected | B6: Delivery Readiness according to Performance Outcomes detailed in this file (Refer "Performance Outcomes" sheet
A8: 4. Measureable units of the outcome | B8: Metrics as defined in "Performance Outcomes" sheet
A10: 5. Who are the target audience? | B10: CDE Interns/GENCs aspiring for 'Software Engineer Trainee' role in CDE career lattice
A12: 6. What is the gating criteria for SET role? | B12: In the Module List, all the red highlighted rows are mandatory gating assessments, in which the students must get greater than 70%
A14: 6. What are the gating assessments and benchmark for the curriculum?

Sheet Summary
B4: Internship - FSE Java Track
B5: Internship | C5: Stage # | D5: Duration in Weeks
C6: Stage 1 | D6: =ModuleList!H2/40 -> 3.09625 | E6: 3
C7: Stage 2 | D7: =ModuleList!H16/40 -> 2.975 | E7: 3
C8: Stage 3 | D8: =SUM(ModuleList!H30:H47)/40 -> 3.3 | E8: 3.5
C9: Stage 4 | D9: =SUM(ModuleList!H48:H59)/40 -> 4.6 | E9: 3.5
C10: MFRP | D10: =ModuleList!H60/40 -> 2.4 | E10: 2.5
B11: Behavioral | C11: BEH | D11: =ModuleList!H63/40 -> 0.6 | E11: 0.6
B12: Org Mandatory Courses (Saturdays) | C12: Org Mandates | D12: =ModuleList!H86/40 -> 2.2625 | E12: 2
B13: Total Curriculum Duration excluding Org Mandatory Courses | D13: =SUM(D6:D11) -> 16.97125
B15: Operations + Assimilation + Buffer | D15: 1.5
B16: Overall FSE Java Duration | D16: =SUM(D13,D15) -> 18.47125

Sheet ModuleList
A1: Stage/Level | B1: Course Segment | C1: Course/Module | D1: Delivery Method | E1: Baseline Duration ( Hours ) | F1: Enablement Assured Level | G1: Assessment Assured Level | H1: Stage wise -Total Duration
A2: Stage 1 (Internship Training - Flipped Classroom Model) | B2: UI & Scripting Technology | C2: HTML/CSS/Javascript | D2: Video Based | E2: 11.5 | F2: Skill | H2: =SUM(E2:E15) -> 123.85
C3: HTML/CSS Practice / Hands-on | D3: Hands-on | E3: 8
C4: Practice case study | D4: Hands-on | E4: 4
C5: Coding Challenge(Web UI) | D5: Hands-on | E5: 4 | G5: Skill
B6: Programming & Database Technology | C6: ANSI SQL Using MySQL | D6: Video Based | E6: 8 | F6: Skill
C7: ANSI SQL Using MySQL Practice / Hands-on | D7: Hands-on | E7: 8
C8: Practice case study | D8: Hands-on | E8: 4 | G8: Skill
C9: Code Challenge (ANSI SQL) | D9: Hands-on | E9: 4
C10: Core Java | D10: Video Based | E10: 12.35 | F10: Skill
C11: Core Java - Practice / Hands-on | D11: Hands-on | E11: 40
C12: Practice case study | D12: Hands-on | E12: 8
C13: Code Challenge(Core Java) | D13: Hands-on | E13: 4 | G13: Skill
B14: Integrated Capability Test | C14: Core Java - Mock Integrated Capability Test/Practice | D14: Hands-on | E14: 4 | G14: Skill
C15: Core Java - Integrated Capability Test | D15: Certification | E15: 4
A16: Stage 2 (Internship Training - Flipped Classroom Model) | B16: Spring Core and Maven | C16: Spring Core and Maven | D16: Video Based | E16: 7 | F16: Skill | H16: =SUM(E16:E29) -> 119
C17: Spring Core and Maven - Practice / Hands-on | D17: Hands-on | E17: 16
C18: Practice case study | D18: Hands-on | E18: 8
C19: Code Challenge(Spring Core and Maven) | D19: Hands-on | E19: 4 | G19: Skill
C20: Agile | D20: Video Based | E20: 2
B21: TDD, Code Quality | C21: TDD, Unit Testing with Mockito,Code Quality | D21: Video Based | E21: 4 | F21: Skill
C22: TDD, Unit Testing with Mockito,Code Quality Practice / Hands-on | D22: Hands-on | E22: 16
C23: Code Challenge(TDD, Unit Testing) | D23: Certification | E23: 4 | G23: Skill
B24: Spring MVC with Spring Boot | C24: Spring MVC with Spring Boot | D24: Video Based | E24: 10 | F24: Skill
C25: Spring MVC with Spring Boot Practice / Hands-on | D25: Hands-on | E25: 24
C26: Practice case study | D26: Hands-on | E26: 8
C27: Code Challenge(Spring MVC with Spring Boot ) | D27: Hands-on | E27: 4 | G27: Skill
B28: Integrated Capability Test | C28: Mock Integrated Capability Test/Practice | D28: Hands-on | E28: 8
C29: Integrated Capability Test | D29: Certification | E29: 4 | G29: Skill
A30: Stage 3 (Internship Training - Traditional Classroom/OBL Model) | B30: Bootstrap | C30: Bootstrap | D30: ILT | E30: 8 | F30: Skill | H30: =SUM(E30:E31) -> 16
C31: Bootstrap / Hands-on | D31: Hands-on | E31: 8 | F31: Skill
B32: JPA, Hibernate, Spring Data JPA | C32: Hibernate, Spring Data JPA | D32: ILT | E32: 8 | F32: Skill | H32: =SUM(E32:E35) -> 32
C33: Hibernate, Spring Data JPA - Practice / Hands-on | D33: Hands-on | E33: 8 | F33: Skill
C34: Practice check in Spring Data JPA | D34: Certification | E34: 8 | G34: Skill
C35: Final check in Spring Data JPA | D35: Certification | E35: 8 | G35: Skill
B36: Logging and Continuous Code Quality | C36: Slf4j and Lombok | D36: ILT | E36: 6 | F36: Skill | H36: =SUM(E36:E39) -> 20
C37: Hands-on | D37: Hands-on | E37: 6 | F37: Skill
C38: SonarQube | D38: ILT | E38: 2 | F38: Skill
C39: Hands-on | D39: Hands-on | E39: 6 | F39: Skill
B40: Design Mindset | C40: Design Principles and Patterns | D40: ILT | E40: 8 | F40: Skill | H40: =SUM(E40:E43) -> 32
...

Sheet Performance Outcomes
A3: Tracks | B3: Competency Type | C3: Key Performance Outcomes | D3: Key Performance Metrics
A4: Academy Java Track - Stage 1 | B4: Technical | C4: Should be able to develop simple user interfaces of a web application Should be able to apply HTML5 Elements and Attributes, Navigation, Events, Geo Location in a web application Should be able to interpret the functional requirements and low level design and develop simple level coding components Should be able to fix simple issues/defects in web UI layer with minimum support Should be able to develop a simple component or module using Java language, following a component design specification Should be able to demonstrate the Object Orientated Programming Concepts, Packages, Interfaces, Abstract Classes, Inner Classes Should be able to analyze and implement the Exception Handling, Strings, I/O, Collections and Generics, Standard Libraries (java.lang, java.util) Should be able to use Multithreading for a simple scenario Should be able to use JDBC to access DB and perform basic operation Should be able to apply Java 8 features Lambda Expressions Should be able to use the Java 8 feature, Method references in the programming Should be able to use the concepts of Functional Interfaces, Default methods Should be able to apply Streaming API in programming concepts Should be able to use Optional class in programming concepts Should be able to explain the concepts of Parallel sort in programming Should be able to use the Java 8 feature, Date/Time API in the programming Should be able to interpret the entities and relationships and create simple tables in database Should be able to describe relationships between tables and write simple queries to retrieve data from the database Should be able to perform CRUD operations using various types of statements, joins, subqueries | D4: - No of code review comments on the delivered code - No of non compliance issues identified against coding process and standards - Adherence to schedule/ timelines (Effort Variance (Actual-planned)/ planned efforts) - Quick turnaround of defect resolution
A8: Academy Java Track - Stage 2 | B8: Technical | C8: Should be able to apply Dependency Injection in a scenario Should be able to describe Spring AOP Should be able to use Property Files Should be able to use Spring JDBC and Transactions for a simple scenario Should be able to write simple unit test cases for a Java Module Should be able to apply annotation based controller configuration Should be able to implement resolvers Should be able to implement unit testing using Junit Framework Should be able to use simple MVC components for coding the presentation layer of a module using Spring Framework Should be able to Initialize a Spring Boot Project Should be able to continuously build a simple application using Maven Should be able to manage Repositories and Dependency Management Should be able to fix simple issues in a simple component of a Spring MVC based application | D8: - No of code review comments on the delivered code - No of non compliance issues identified against coding process and standards - Adherence to schedule/ timelines (Effort Variance (Actual-planned)/ planned efforts) - Quick turnaround of defect resolution
A9: Academy Java FSE Track - Stage 3 | B9: Technical | C9: Should be able to design simple components or refactor existing components by applying design principles and patterns Should be able to write DAO layer with ORM concepts using Hibernate, Spring Data JPA Should be able to perform basic CRUD operations using Hibernate, Spring Data JPA Should be able to apply the concepts of Mapping in Spring Data JPA Should be able to apply the concepts of Persistent Objects, HQL in Spring Data JPA Should be able to use Lombok for slf4j logging Should be able to use SONAR for analysing source code and fix the issues Should be able to configure SONAR using Maven Should be able to design web pages using RWD principles Should be able to apply simple problems using algorithms and simple data structures | D9: - No of code review comments on the delivered code - No of non compliance issues identified against coding process and standards - Adherence to schedule/ timelines (Effort Variance (Actual-planned)/ planned efforts) - Quick turnaround of defect resolution
A10: Academy Java FSE Track - Stage 4 | B10: Technical | C10: Should be able to develop a simple REST web service using Spring Boot Should be able to Demonstrate the concepts of Spring Boot, Components of RESTful Web Services and REST Fundamentals Should be able to develop Web Applications using REST End Points with Spring Boot Should be able to write Test cases for testing a REST web service Should be able to mock services and test a REST service Should be able to explain the concepts of Distributed/versioned configuration Should be able to use API gateway, Load Balancing , Fault Tolerance, Circuit Breaker, Service Broker Should be able to explain distributed messaging Service Should be able to convert a simple monolithic app to a Microservice Should be able to use centralized Microservices Configuration with Spring Cloud Should be able to secure microservices using JWT Should be able to explain on how to containerize a web app using Docker Should be able to describe various services of AWS Should be able to Explain Cloud computing basics and principles Should be able to Explain the Microservices Design Principles Should be able to Explain the Container Concepts Should be able to Use the Container Management - use the existing container environment and deploy the container in cloud Should be able to deploy a simple application in AWS using already laid out CI/CD pipeline Should be able to describe the concepts of DevOps, CI/CD Should be able to deploy the Microservice in AWS cloud platform Should be able to explain the benefits of container orchestration using Kubernetes | D10: - No of code review comments on the delivered code - No of non compliance issues identified against coding process and standards - Adherence to schedule/ timelines (Effort Variance (Actual-planned)/ planned efforts) - Quick turnaround of defect resolution

Sheet Skill Framework
A2: Java Skill Framework - ADM, AVM, FSE
A3: Technology Layer | B3: Technology Category | C3: Proficiency | D3: Academy Java Track - Stage 1 | E3: Academy Java Track - Stage 2 | F3: Academy Java FSE Track - Stage 3 | G3: Academy Java FSE Track - Stage 4
A4: Programming Language | B4: Programming Language | C4: PL1 - Learner | D4: Java
B5: Scripting Language | C5: PL1 - Learner | D5: JavaScript
A6: Presentation Layer | B6: Basic UI/Markup | C6: PL1 - Learner | D6: HTML5
D7: CSS3
B8: Responsive Web Design | C8: PL1 - Learner | F8: Bootstrap
B9: Web Frameworks | C9: PL1 - Learner | E9: Spring MVC
E10: Java Server Pages
E11: Servlets
E12: JSTL
A13: Middleware | B13: Business Tier | C13: PL1 - Learner | E13: Spring Core
E14: Spring Boot
B15: Persistence Tier | C15: PL1 - Learner | F15: Hibernate, Spring Data JPA
B16: Integration Tier | C16: PL1 - Learner | G16: Spring REST
A17: Data Layer | B17: Query Languages | C17: PL1 - Learner | D17: ANSI SQL
B19: RDBMS/No-SQL | C19: PL1 - Learner | D19: MySQL
A20: Ancillary Layer | B20: Common Utilities | C20: PL1 - Learner | D20: Eclipse
D21: MySQL Workbench
E22: Spring Tool Suite | F22: SONAR Qube, Lombok Logging
B24: Platform and OS | C24: PL1 - Learner | E24: Windows
B25: Unit Testing | C25: PL1 - Learner | E25: Junit, Mockito
B29: Security | G29: Spring Security with Spring Boot, JWT
B30: Servers | C30: PL1 - Learner | E30: Tomcat
A31: Software Architecture, Data Structures and Algorithms, Design Principles, Patterns and Tools | B31: Software Architecture | C31: PL1 - Learner | E31: MVC
B32: Design Principles, Patterns and Tools | C32: PL1 - Learner | D32: Object Oriented Principles | F32: Design Patterns and Principles
B33: Algorithms | F33: Data Structures and Algorithms
A34: Cloud and DevOps | B34: CI/CD | C34: PL1 - Learner | E34: Maven | G34: DevOps, CI/CD on AWS
B35: Containerization | C35: PL1 - Learner | G35: Docker
B36: Cloud | C36: PL1 - Learner | G36: AWS, Spring Cloud
B37: Orchestration | C37: PL1 - Learner | G37: Kubernetes

Sheet Stage 1-Scope
A1: Stage 1 - Technical Scope
A2: Proficiency Level: Learner
A3: Skill | B3: Topic | C3: Sub Topics
A4: HTLM5 | B4: HTML5 - Introduction | C4: Need and Benefits of HTML, Setup, Browser, BOM and DOM, DOCTYPE, Character Encoding, <script> , <link>, , HTML5 Document, Comments
A5: HTLM5 | B5: HTML5 - Getting Started | C5: Visual Studio Code features, Google Chrome Developer tools, Inspect document
A6: HTLM5 | B6: HTML5 - Elements & Attributes | C6: Formatting Tags, List, Table, Form & Input Tags, Images, Styles, placeholder, inline and block elements, id vs class attributes
A7: HTLM5 | B7: HTML5 - Navigation | C7: Navigation tags, hyper link, reference to intermediate section
A8: HTLM5 | B8: HTML5 - Events | C8: onblur, onchange, onclick, form related events, load events, key events, mouse events, ondblclick, onbeforeonload, oncanplay
A9: HTLM5 | B9: HTML5 - Web Forms 2.0 HTML5 - Web Storage HTML5 - Web SQL Database | C9: <input> element in HTML5, <output>, placeholder attribute, autofocus, required Session storage, local storage and Delete web storage openDatabase, transaction, transaction
A10: HTLM5 | B10: HTML5 - Geo location | C10: Geolocation Methods, Location Properties, Handling Errors, Position Options
A11: CSS3 | B11: CSS3 - Introduction | C11: Need and Benefits of CSS, Setup, CSS Syntax, CSS Comments, Including CSS in HTML Documents(Inline styles, Embedded styles, External style sheets)
A12: CSS3 | B12: CSS3 - Selectors | C12: CSS3 Selectors - Universal Selector, Element Type Selector, Id Selectors, Class Selectors, Grouping Selectors
A13: CSS3 | B13: CSS3 - Styling | C13: CSS Color, CSS Background, CSS Fonts, CSS Text, CSS Links, CSS Lists, CSS Tables
A14: CSS3 | B14: CSS3 - Box Model | C14: CSS Box Model, Margin, padding, border, Outline, Visibility vs. Display, Multiple Columns
... A16: JavaScript | B16: JavaScript Fundamemtals | C16: JavaScript Basics, DOM
A17: JavaScript | C17: Variables, Datatypes, Type Conversions, Operators, Comparisons, Interactions, Loops, Functions, Function expression, Control Flow, Conditionals
A18: JavaScript | B18: Javascript Deep Dive | C18: Array, String, Date, Math, Number, Boolean, Functions, JSON, Regular Expression
A19: JavaScript | C19: Objects, Arrays and Functions, JSON
A20: SQL Scripting | B20: Introduction to Databases | C20: Introduction to SQL/NoSQL, Advantages and Disadvantages
B21: Connecting to the Database, Normalization Forms | C21: Table and Views
B22: Basic CRUD operations, Functions, Expressions and Clauses | C22: DDL, DML, Query and Operations, Clauses, Aggregate Functions, String Functions, GROUP BY, Having, Rank Functions
B23: Joins and Subqueries | C23: Joins, Sub queries
A24: Core Java Fundamentals | B24: Object Oriented Programming Concepts | C24: Principles of OOP, Inheritance, Polymorphism, Classes, Methods, Coupling and Cohesion, Abstraction, Encapsulation, Constructors
B25: Packages, Interfaces, Abstract Classes, Inner Classes | C25: Overloading, Overriding, Abstract Classes, Implementing Interfaces, Access Protection, Using this, super and final, Object Class, Inner Classes, Anonymous Inner Classes, Method-Local Inner Classes, Static Nested Classes
B26: Exception Handling | C26: Handling Exceptions, Propagating and Catching Exceptions, Uncaught Exceptions, Subclassing Exceptions, try, catch, throw, throws, finally
B27: Strings, I/O, Collections and Generics, Date/Time API, Standard Libraries (java.lang, java.util) | C27: String, StringBuilder, StringBuffer, StringTokenizer, File Navigation and I/O (java.io), Numbers, Calendar, Locale, Scanner, ResourceBundle and Currency, Parsing, Tokenizing, Formatting, Collection Interfaces, Collection Classes, Iterators, Comparators, Generic and Non-Generic Collections, Primitive Wrappers, Comparable Interface, Math, ClassLoader, System, Process, Runtime, LocalDate, LocalTime,LocalDateTime, Instant, Duration, Period, TemporalAdjusters
A28: Core Java Deep Dive | B28: Multithreading, Sorting in Java | C28: Creating a Thread, Suspending, Resuming and Stopping Threads, Serial and Parallel Sorts in Java
B29: JDBC | C29: Create Connection, Query, Update
B30: Lambda Expressions | C30: Lambda expressions (with Single parameter, multiple parameters, return type, collections, forEach, Multiple statements, without return type), Reference to a static method, Reference to an instance method, Reference to a constructor, Usage of Functional interfaces and default methods
B31: Streams and Optionals | C31: Java Stream vs. Collection, Different ways to create streams(Stream.of(), List.stream(), Stream.generate() or Stream.iterate(),String chars or String tokens),Convert streams to collections, Intermediate Operations (filter(),map(),flatMap(),distinct(),sorted(),peek(),limit(),skip()) Terminal Operations (forEach(),forEachOrdered(),toArray(),reduce(),collect(),min(),max(),count(),anyMatch(),allMatch(),noneMatch(),findFirst(),findAny()), Parallelism in Java Stream Optional.empty(), Optional.of(), Optional.ofNullable(), ifPresent(), isPresent(), orElse(), orElseThrow(), filter() Asynchronous and Parallel Programming in Java 8 - Threads, Completable Future, Future, Parallel Streams

Sheet Stage 2-Scope
A1: Stage 2 - Technical Scope
A2: Proficiency Level: Learner
A3: Skill | B3: Topic | C3: Sub Topics
A4: Spring Core | B4: Dependency Injection | C4: Setter Injection
C5: Constructor Injection
C6: Autowiring
C7: Injecting Collections
C8: Inner Beans
C9: Inheritance, Interfaces, Scope
B10: Spring AOP | C10: Aspect Oriented Programming (AOP) using Spring AOP and AspectJ
B11: Reading values from Property Files | C11: PropertyPlaceholderConfigurer , ResourceBundleMessageSource
B12: Spring JDBC and Transactions | C12: Executing Queries, Transaction Management
A13: Maven | B13: Maven Basics | C13: Maven (Local, Remote and Central Repo) Setup Maven Manage Repositories and Dependency Management Managing dependent libraries, building and deploying project, create package (jar or war) Integrate Maven with Eclipse Manage testing and deployment options
B14: Build life cycle | C14: Build life cycle, Using environment variables JAVA_HOME, MAVEN_HOME, PATH, mvn -version Create, build and deploy a maven project (Using Eclipse and Command Line) Various aspects available in pom.xml - groupId, artifactId, version, packaging, dependencies, dependency scope (compile, provided, runtime, test, system), properties
B15: Plugins | C15: Plugins
B16: Run Maven Builds | C16: Running Maven Builds for a sample Spring Project
A17: Junits | B17: Unit Testing Fundamentals | C17: TDD Fundamentals
C18: Environment Setup, Assertions, Execution Procedure, Executing Tests
C19: Basic Tests using Junits
C20: Parameterized Tests
C21: Composing and running a test suite
C22: Refactoring code, using setup and teardown
C23: Using Mockito - Mocking a database, expecting calls, exception handling, callbacks, resetting mock, timeouts
A24: Code Quality | B24: PMD, Checkstyle, FindBugs | C24: Running PMD rulesets for checking Code Quality
C25: Use Checkstyle, SONAR, Findbugs, FxCopAnalyzers
C26: Refactoring code to improve code quality
C27: Practice to generate the code quality report with no errors and minimum warnings
A28: Spring MVC with Spring Boot | B28: Spring MVC Fundamentals | C28: Introduction to Application Servers (Tomcat)
C29: JSP, Servlets, JSTL
B30: Spring MVC with Spring Boot | C30: Initializing and Auto Configuring Spring Boot App
C31: Configuring Web App using Spring Boot
C32: Spring MVC Tag Libraries
C33: View Resolvers
C34: Controllers
C35: Internationalization
C36: Data Binding, Validation and Exception Handling

Sheet Stage3-Scope
A1: Stage 3 - Technical Scope
A2: Proficiency Level: Learner
A3: Skill | B3: Topic | C3: Sub Topic
A5: Bootstrap | B5: Bootstrap Fundamentals | C5: Responsive Web Design (RWD), Disadvantages of sites without RWD, Mobile First design, Bootstrap 4, emulate devices in Chrome Browser
C6: doctype, viewport meta tag and attributes, Bootstrap CDN
B7: Grid System | C7: Grid System, 12 columns, devices and corresponding prefix of bootstrap class, container, container-fluid, row, col-
B8: NAV Bar | C8: navbar, navbar-expand-lg, navbar-dark, bg-dark, navbar-brand
C9: navbar-nav, nav-item, nav-link
C10: navbar-toggler, navbar-toggler-icon, collapse, navbar-collapse, ml-auto
B11: Demonstrate troubleshooting UI issues using Chrome Developer Tools | C11: Element selection
C12: 1) using Inspect
C13: 2) selection tool in Developer Console
C14: 3) Hovering over the elements in the HTML code within the "Element" section of Developer Tool
C15: Applying Styles directly using Developer Tools
C16: 1) Add new style in the style window
C17: 2) Disable an existing style using the checkbox
C18: 3) Change value of an existing style
B19: Bootstrap Components | C19: badge, badge-primary
C20: Google Material Icon, Content Delivery Network (CDN), include icons in web page
C21: list-group, list-group-item
C22: card, card-title, card-body, card-text, change mouse cursor on hovering an icon
C23: Display a list of cards using grid system and thus enabling RWD
C24: gijgo, getting started, setting date format
C25: Develop form with textbox, password, drop down, date using gijgo, radio button and checkbox form-row, form-group, form-control, form-check, form-check-input, form-check-label, form-check-input
B26: Bootstrap Styles | C26: Separate CSS file for customization, overriding the styles of Bootstrap
A27: JPA, Hibernate, Spring Data Access JPA with Spring Boot | B27: ORM Basics | C27: ORM (Object-Relational Mapping), makes it easier to develop code that interacts with database, abstracts the database system, transactionality
B28: ORM Basics | C28: Evolution of ORM solutions, Hibernate XML Configuration, Hibernate Annotation Configuration, Spring Data JPA, Hibernate benefits, open source, light weight, database independent query
B29: Hibernate Basics | C29: Session Factory, Session, Transaction Factory, Transaction, Connection Provider
B30: ORM implementation with Hibernate XML Configuration and Annotation Configuration | C30: XML Configuration - persistence class, mapping xml, configuration xml, loading hibernate configuration xml file Annotation Configuration - persistence class, @Entity, @Table, @Id, @Column, hibernate configuration xml file Loading hibernate configuration and interacting with database get the session factory, open session, begin transaction, commit transaction, close session
B31: Hibernate Basics | C31: JPA (Java Persistence API), JPA is a specification (JSR 338), JPA does not have implementation, Hibernate is one of the implementation for JPA, Hibernate is a ORM tool, Spring Data JPA is an abstraction above Hibernate to remove boiler plate code when persisting data using Hibernate.
B32: Mapping, Persisting objects into database, Detatched Objects | C32: Hibernate log configuration and ddl-auto configuration, JpaRepsitory.findById(), defining Query Methods, JpaRespository.save(), JpaRepository.deleteById()
C33: Query Methods - Search by containing text, sorting, filter with starting text, fetch between dates, greater than or lesser than, top
C34: @ManyToOne, @JoinColumn, @OneToMany, FetchType.EAGER, FetchType.LAZY, @ManyToMany, @JoinTable, mappedBy
B35: HQL | C35: HQL stands for Hibernate Query Language, JPQL stands for Java Persistence Query Language, Compare HQL and JPQL, @Query annotation, HQL fetch keyword, aggregate functions in HQL, Native Query, nativeQuery attribute
B36: Criteria | C36: Scenarios where Criteria Query helps, CriteriaBuilder, Criteria Query, Root, TypedQuery
A37: Logging, and Continuous Code Quality | B37: SLF4J, Lombok | C37: SLF4J vs. Log4J vs. Lombok
C38: SLF4J - Env Setup, Sample Logging
C39: SLF4j - error messages, warning levels, parameterized logging, different appenders
C40: Lombok - Configuring Project using Lombok
C41: Logging using Lombok annotations
...

Sheet Stage 4-Scope
A1: Stage 4 - Technical Scope
A2: Proficiency Level: Learner
A3: Skill | B3: Topic | C3: Sub Topic
A5: Spring REST with Spring Boot | B5: Spring Boot Introduction for Spring REST | C5: Spring initializr, https://start.spring.io, @SpringBootApplication, SpringApplication.run()
C6: Makes Java development easy, avoids tedious development steps, reduces development time, avoids writing boilerplate code, provides embedded tomcat server, avoid XML configuration
C7: Spring configuration xml, spring xml schema spring-beans.xsd, <bean>, id, class, <constructor-arg>, <property>, name, value, ClassPathXmlApplicationContext, ApplicationContext, context.getBean(), singleton scope, prototype scope
C8: Spring Boot CLI and Initializing a Spring Boot Project - Working with Spring Boot Starters Overriding auto-configured beans "Reducing code with custom auto configurations - @EnableAutoConfiguration - writing own custom auto configuration" Configuring with external properties Customizing Error Pages Spring Boot Dependency Management
C9: application.properties, logging.level, logging.pattern, server.port, LoggerFactory, Logger, log levels (trace, debug, info, warn, error)
B10: REST Web Services Introduction | C10: HTTP Request and Response, HTTP Request Format, HTTP Response Format, Request URL, Request Method, Content-Type, User-Agent
C11: The need to transfer data between heterogenous systems, disadvantages of SOAP, REST stands for REpresentational State Transfer, lightweight, maintainable, scalable, underlying protocol is HTTP; composed of resources, verbs, header, body, response status code, client-server technology
B12: Producing and Consuming REST services | C12: DispatcherServlet, @RestController, @GetMapping, invoking get request from browser, invoking get request from postman, bean transformation to JSON, APIs for bean to JSON and vice versa, Jersey, Jackson, get method with parameter, return array, @PathVariable
C13: REST Web Service architecture with Controller, Service and Dao, service methods, invoking service using http client in Spring MVC, cross origin, Errors and Exception Handling, Writing a REST Client, Modifying Response Formats (Content negotiation), Building custom response using Response Entity.
C14: HTTP method types (GET, POST, PUT, DELETE), REST service URL naming guidelines, @RequestMapping, @GetMapping, @PostMapping, @PutMapping, @DeleteMapping, setting POST request payload and invoking the REST service in Postman and curl, JSON to bean mapping, @RequestBody, validating input request using javax.validation and hibernate validators, @Size, @NotNull, @NotBlank, @Min, @Max, @JsonFormat, @Valid, global exception handling, handle number formatting errors, HTTP Caching, Retrieving LIST in REST, Writing a RESTful Web Services with JSON
B15: Testing Restful Webservices uisng Mock MVC | C15: @AutoConfigureMockMvc, MockMvc, @Test, get(), perform(), andExpect(), status().isOk(), jsonPath().exists, jsonPath().value(), status().isBadRequest(), status().reason test execution in Eclipse, test execution in command line using maven
A16: Spring Security with Spring REST and Spring Boot | B16: Spring Security using OAuth2 and JSON Web Tokens (JWT) | C16: Introduction to OAuth2, Spring Security for OAuth2, Steps Involved in User Authentication, Auth Server, Resource Server, JWT tokens Configuring Libraries in Maven Create Oauth Config Class to define secret keys, public private keys , token validity and scopes Write a Spring Boot RESt application, use Auth and Resource Servers Try triggering REST requests with and without valid tokens and checking response
A17: Microservices and Docker | B17: Microservices Basics, Monolithic to Microservices | C17: Spring RESTful Web Services, server.port definition
B18: Spring Cloud | C18: Distributed/versioned configuration Service registration and discovery Routing Service-to-service calls Load balancing Circuit Breakers Distributed messaging Using the above concepts: 1. Decompose the monolith application built earlier into micrroservices 2. Write the microservices using Spring Boot. Expose each as a REST service 3. Demonstrate features of spring cloud like API Gateway, Load balancer, Circuit breaker, Service discovery for microservices used to address the challenges of a distributed architecture 4. Securing Microservices with Security
B19: Introduction to Docker | C19: Container Introduction, Container architecture, Overview of Docker, Docker architecture Docker file Working with containers Container Communication Docker Compose open source; create, deploy and run applications in containers; package application; virtual machine; image; container
B20: Hosting App using nginx, using command line and Dockerfile | C20: nginx, pull, run, listing images, container name, detaching the process, port number, volumes, listing containers, listing non running containers, starting and stoping a container, Dockerfile, FROM, COPY, ENTRYPOINT, build, remove images and containers
B21: Hosting a MySQL database with schema creation using docker | C21: docker-compose.yml, docker-compose up command, mapping MySQL data file to local folder, schema creation script execution definition, defining port, password definition, docker compose up, executing mysql client on the mysql server container
B22: Hosting a REST API Microservice using docker | C22: Defining Dockerfile for REST API, building Dockerfile from docker-compose.yml, using depends_on in docker compose to define dependencies, using links to establish connectivity between REST API service and MySQL server, modify connection properties in REST API to connect to the docker instance
A23: Kubernetes - Container Orchestration | B23: Introduction to Kubernetes | C23: What, Why and Features of Kubernetes, Kubernetes Architecture Kubernetes Cluster, Master, Node Kubernetes Architecture Kubernetes Basics Modules ( Create a Kubernetes Cluster, Deploy an App, Explore your App, Expose your app publicly, Scale up your App, Update your app)
B24: Kubernetes Demonstration | C24: Deploy the container image created earlier on A Kubernetes cluster. Use an open source framework like Minikube for a standalone deployment
C25: Kubernetes Cluster, Master, Node
A26: AWS, CI/CD | B26: Introduction to cloud computing | C26: Cloud Introduction, Difference between on-premise server and cloud offerings - Server, Storage, Service, PAAS, SAAS. IAAS, Private cloud, Public cloud
B27: Containers | C27: Introduction to Containers. Containers vs VM
B28: Fundamentals of AWS | C28: Global cloud infrastructure of AWS (Regions, AZ), Cloud services -- Compute, Storage, Database, Container
B29: CI/CD in AWS | C29: Introducing devops (CI/CD) on AWS
B30: Deploying an application on AWS | C30: Learn how to automate a web application deployment using Services like Elastic Beanstalk. Create environment in AWS containing VPC, ELB, EC2 Instances, Subnets, Security groups …for deploying different web applications
B31: Introduction to Devops -- CI/CD on cloud on AWS | C31: Introducing DevOps, CI/CD stack-- Code Commit, Code Build, Code Deploy, Code Pipeline, Code Star
B32: CI/CD hands on lab | C32: CI/CD with AWS Code services.
B33: CI/CD with microservices deployed on ECS/EKS | C33: Setup Codepipeline within the AWS environment that will automate the build & deployment of microservices containers on ECS / EKS. Developers will write / enhance microservices & commit it to the source control repository. They will then watch how the CI/CD is automatically executed without downtime to the existing service TASKS: 1. Setting up code repository for microservices 2. Infrastructure automation setup 3. Infrastructure creation using automation scripts 4. Use the CI/CD infrastructure & check automated build, deploy of artifacts on the container instances. Eg for ECS, the build should create a container image of a microservice & push it to the ECR repository, The deploy should deploy the container images on the ECS cluster having a task definition, Service, Target group 5. The above process should be repeated so that any changes to the source code will result in the containers being automatically updated to reflect the new change

Sheet JavaReference
A1: Java/Dotnet | B1: Client/server | C1: Skill list | D1: Duration
A5: HTML and CSS | B5: ILT | C5: 16 | D5: Skill
A6: XML | B6: ILT | C6: 8 | D6: Skill
A7: JavaScript | B7: ILT | C7: 16 | D7: Skill
A9: HTML | B9: Elearning | C9: 2 | D9: Knowledge
A10: XML | B10: Elearning | C10: 2 | D10: Knowledge
A11: JavaScript | B11: Elearning | C11: 4 | D11: Knowledge

Sheet DotnetReference (2)
A1: Java/Dotnet | B1: Client/server | C1: Skill list | D1: Duration
A5: HTML and CSS | B5: ILT | C5: 16 | D5: Skill | E5: Skill
A6: XML | B6: ILT | C6: 8 | D6: Skill | E6: Skill
A7: JavaScript | B7: ILT | C7: 16 | D7: Skill | E7: Skill
A8: ASP.Net | B8: ILT | C8: 36 | D8: Skill | E8: Knowledge
A9: ASP .NET MVC | B9: ILT | C9: 20 | D9: Skill | E9: Knowledge
A11: HTML | B11: Elearning | C11: 2 | D11: Knowledge | E11: Knowledge
A12: XML | B12: Elearning | C12: 2 | D12: Knowledge | E12: Knowledge
A13: JavaScript | B13: Elearning | C13: 4 | D13: Knowledge | E13: Knowledge
A14: ASP.Net | B14: ILT | C14: 36 | D14: Skill | E14: Knowledge
A15: ASP.Net MVC (Not Needed) | C15: 0
